Workbook
Name UPDATE: 'Data Sheet'!$E$1

Sheet Cover
B2: Titan Company Ltd — 3-Statement Financial Model
B3: Consolidated | ₹ Crore | FY ends 31 March | Actuals FY17–FY26, Forecast FY27E–FY31E
B5: Company | C5: Titan Company Ltd (NSE: TITAN) — jewellery (Tanishq, Mia, CaratLane), watches & wearables, eyecare, fragrances
B6: Why this company | C6: Simple, asset-light retail/manufacturing model: revenue → margins → working capital (mostly gold inventory) → cash. Not a bank/NBFC/insurer.
B7: Data source | C7: Screener.in consolidated financials (https://www.screener.in/company/TITAN/consolidated/), incl. balance-sheet and expense schedules; pulled 25-Sep-2026.
B8: Purpose | C8: Worked example / learning template. Forecast assumptions are illustrative, not investment advice.
B10: Colour legend
B11: 1234 | C11: Blue text = hard-coded input (historical data or forecast assumption)
B12: 1234 | C12: Black text = formula / calculation on the same sheet
B13: 1234 | C13: Green text = direct link pulled from another sheet
B14: 1234 | C14: Yellow fill = key forecast driver — change these to run your own scenarios
B15: 1234 | C15: Grey fill = forecast period columns
B17: Sheet map (follow in this order)
B18: Summary | C18: One-page output with key numbers, valuation snapshot and charts.
B19: Assumptions | C19: All forecast drivers in one place, change according to the chosen company.
B20: Historical FS | C20: Historical three Statements of previous 10 years linked with Screener raw data.
B21: Forcasting | C21: Income Statement, Balance Sheet, Cash Flow Statement — historical + forecast.
B22: FA_Schedule | C22: Fixed-asset & depreciation roll-forward, CWIP and Investment.
B23: WC_Schedule | C23: Working-capital schedule: inventory, receivables, payables, advances, other items.
B24: Debt_Schedule | C24: Borrowings and interest.
B25: Ratios | C25: Growth, EBITDA margin, net margin, ROE, ROCE, Debt/Equity and more.
B26: Checks | C26: Balance check (Assets = Liabilities + Equity), cash tie-out, roll-forward checks.
B28: Key simplifications
C29: • Screener gives cost lines as rounded % of sales; material & employee costs are rebuilt from those %s, and 'Other expenses' is the balancing figure so total expenses match exactly.
C30: • Historical cash flow is shown as reported (CFO/CFI/CFF totals). Screener's 'Cash Equivalents' on the balance sheet uses a narrower definition, so historical net cash flow won't tie to the change in BS cash — the forecast ties exactly.
C31: • Dividends are assumed paid in the same year as the profit (Titan actually pays the final dividend in the next year).
C32: • Lease liabilities, CWIP, investments and share capital are held flat in the forecast.
C33: • Minority interest is not modelled separately (small for Titan).

Sheet Summary
B2: ="EXECUTIVE SUMMARY — " & 'Data Sheet'!B1 -> EXECUTIVE SUMMARY — TITAN COMPANY LTD
B3: Years | C3: ='Historical FS'!H3 -> 44651 | D3: ='Historical FS'!I3 -> 45016 | E3: ='Historical FS'!J3 -> 45382 | F3: ='Historical FS'!K3 -> 45747 | G3: ='Historical FS'!L3 -> 46112 | H3: =+G3+365 -> 46477 | I3: =+H3+365 -> 46842 | J3: =+I3+365 -> 47207 | K3: =+J3+365 -> 47572 | L3: =+K3+365 -> 47937
B4: ₹ Values are in Cr.
A5: # | B5: KEY FINANCIALS | N5: VALUATION SNAPSHOT
B6: Revenue | C6: =Forcasting!C6 -> 28799 | D6: =Forcasting!D6 -> 40575 | E6: =Forcasting!E6 -> 51084 | F6: =Forcasting!F6 -> 60456 | G6: =Forcasting!G6 -> 87584 | H6: =Forcasting!H6 -> 106852.48 | I6: =Forcasting!I6 -> 125017.4 | J6: =Forcasting!J6 -> 143770.01 | ... L6: =Forcasting!L6 -> 185204.53 | N6: Current Price (₹) | O6: ='Data Sheet'!B8 -> 4815
B7: Revenue Growth % | C7: =Forcasting!C7 -> 0 | D7: =Forcasting!D7 -> 0.40890309 | E7: =Forcasting!E7 -> 0.25900185 | F7: =Forcasting!F7 -> 0.18346253 | G7: =Forcasting!G7 -> 0.44872304 | H7: =Forcasting!H7 -> 0.22 | I7: =Forcasting!I7 -> 0.17 | J7: =Forcasting!J7 -> 0.15 | ... L7: =Forcasting!L7 -> 0.13 | N7: Market Cap (₹ Cr) | O7: ='Data Sheet'!B9 -> 427469.02
B8: EBITDA | C8: =Forcasting!C18 -> 3344 | D8: =Forcasting!D18 -> 4882 | E8: =Forcasting!E18 -> 5292 | F8: =Forcasting!F18 -> 5694 | G8: =Forcasting!G18 -> 8357 | H8: =Forcasting!H18 -> 9616.7232 | I8: =Forcasting!I18 -> 12501.74 | J8: =Forcasting!J18 -> 15095.851 | ... L8: =Forcasting!L18 -> 20372.498 | N8: Shares Outstanding (Cr) | O8: ='Data Sheet'!B6 -> 88.778613
B9: EBITDA Margin % | C9: =Forcasting!C19 -> 0.11611514 | D9: =Forcasting!D19 -> 0.12032039 | E9: =Forcasting!E19 -> 0.10359408 | F9: =Forcasting!F19 -> 0.0941842 | G9: =Forcasting!G19 -> 0.095416971 | H9: =Forcasting!H19 -> 0.09 | I9: =Forcasting!I19 -> 0.1 | J9: =Forcasting!J19 -> 0.105 | ... L9: =Forcasting!L19 -> 0.11 | N9: P/E (x), FY26A EPS | O9: =IFERROR(O6/Forcasting!G41,0) -> 84.264873
B10: Net Profit | C10: =Forcasting!C36 -> 2198 | D10: =Forcasting!D36 -> 3274 | E10: =Forcasting!E36 -> 3496 | F10: =Forcasting!F36 -> 3337 | G10: =Forcasting!G36 -> 5073 | H10: =Forcasting!H36 -> 4791.819 | I10: =Forcasting!I36 -> 6446.4006 | J10: =Forcasting!J36 -> 7856.3725 | ... L10: =Forcasting!L36 -> 10673.053 | N10: P/B (x), FY26A | O10: =IFERROR(O6/((Forcasting!G50+Forcasting!G51)/Forcasting!G39),0) -> 27.22255
B11: Net Profit Margin % | C11: =Forcasting!C37 -> 0.076322095 | D11: =Forcasting!D37 -> 0.08069008 | E11: =Forcasting!E37 -> 0.068436301 | F11: =Forcasting!F37 -> 0.055197168 | G11: =Forcasting!G37 -> 0.057921538 | H11: =Forcasting!H37 -> 0.044845183 | I11: =Forcasting!I37 -> 0.051564026 | J11: =Forcasting!J37 -> 0.054645419 | ... L11: =Forcasting!L37 -> 0.057628466 | N11: Net Debt / EBITDA (x), FY26A | O11: =IFERROR((Forcasting!G52-Forcasting!G68)/Forcasting!G18,0) -> 3.4347254
B12: EPS (₹) | C12: =Forcasting!C41 -> 24.757828 | D12: =Forcasting!D41 -> 36.877675 | E12: =Forcasting!E41 -> 39.378238 | F12: =Forcasting!F41 -> 37.587294 | G12: =Forcasting!G41 -> 57.141248 | H12: =Forcasting!H41 -> 53.974926 | I12: =Forcasting!I41 -> 72.612089 | J12: =Forcasting!J41 -> 88.493977 | ... L12: =Forcasting!L41 -> 120.22099
B13: DPS (₹) | C13: =Forcasting!C44 -> 7.5185853 | D13: =Forcasting!D44 -> 10.02478 | E13: =Forcasting!E44 -> 11.027258 | F13: =Forcasting!F44 -> 11.027258 | G13: =Forcasting!G44 -> 15.037171 | H13: =Forcasting!H44 -> 15.112979 | I13: =Forcasting!I44 -> 20.331385 | J13: =Forcasting!J44 -> 24.778314 | ... L13: =Forcasting!L44 -> 33.661878 | N13: MODEL HEALTH
N14: Status | O14: =Checks!C13 -> ALL CHECKS OK
A15: # | B15: BALANCE SHEET & RETURNS
B16: Total Assets | C16: =Forcasting!C71 -> 21188 | D16: =Forcasting!D71 -> 27020 | E16: =Forcasting!E71 -> 31547 | F16: =Forcasting!F71 -> 40645 | G16: =Forcasting!G71 -> 60561 | H16: =Forcasting!H71 -> 71708.97 | I16: =Forcasting!I71 -> 84510.841 | J16: =Forcasting!J71 -> 98414.282 | ... L16: =Forcasting!L71 -> 128654.21
B17: Total Borrowings | C17: =Forcasting!C52 -> 7275 | D17: =Forcasting!D52 -> 9367 | E17: =Forcasting!E52 -> 15528 | F17: =Forcasting!F52 -> 20777 | G17: =Forcasting!G52 -> 30621 | H17: =Forcasting!H52 -> 36132.78 | I17: =Forcasting!I52 -> 41552.697 | J17: =Forcasting!J52 -> 46954.548 | ... L17: =Forcasting!L52 -> 56810.307
B18: Net Debt (Borrowings − Cash) | C18: =Forcasting!C52-Forcasting!C68 -> 5702 | D18: =Forcasting!D52-Forcasting!D68 -> 8024 | E18: =Forcasting!E52-Forcasting!E68 -> 14002 | F18: =Forcasting!F52-Forcasting!F68 -> 19193 | G18: =Forcasting!G52-Forcasting!G68 -> 28704 | H18: =Forcasting!H52-Forcasting!H68 -> 30744.447 | I18: =Forcasting!I52-Forcasting!I68 -> 33904.928 | J18: =Forcasting!J52-Forcasting!J68 -> 36589.602 | ... L18: =Forcasting!L52-Forcasting!L68 -> 41222.686
B19: Debt / Equity (x) | C19: =Forcasting!C52/SUM(Forcasting!C50:C51) -> 0.7820058 | D19: =Forcasting!D52/SUM(Forcasting!D50:D51) -> 0.79039743 | E19: =Forcasting!E52/SUM(Forcasting!E50:E51) -> 1.653146 | F19: =Forcasting!F52/SUM(Forcasting!F50:F51) -> 1.7874226 | G19: =Forcasting!G52/SUM(Forcasting!G50:G51) -> 1.9500096 | H19: =Forcasting!H52/SUM(Forcasting!H50:H51) -> 1.8865229 | I19: =Forcasting!I52/SUM(Forcasting!I50:I51) -> 1.7463139 | J19: =Forcasting!J52/SUM(Forcasting!J50:J51) -> 1.594322 | ... L19: =Forcasting!L52/SUM(Forcasting!L50:L51) -> 1.3050706
B20: Return on Equity % | C20: ='Ratio Analysis'!C23 -> 0.23626787 | D20: ='Ratio Analysis'!D23 -> 0.27626361 | E20: ='Ratio Analysis'!E23 -> 0.37219206 | F20: ='Ratio Analysis'!F23 -> 0.28707846 | G20: ='Ratio Analysis'!G23 -> 0.32305929 | H20: ='Ratio Analysis'!H23 -> 0.25018491 | I20: ='Ratio Analysis'!I23 -> 0.27091957 | J20: ='Ratio Analysis'!J23 -> 0.26675984 | ... L20: ='Ratio Analysis'!L23 -> 0.24518592
B21: Return on Capital Employed % | C21: ='Ratio Analysis'!C21 -> 0.17764507 | D21: ='Ratio Analysis'!D21 -> 0.20930342 | E21: ='Ratio Analysis'!E21 -> 0.18891698 | F21: ='Ratio Analysis'!F21 -> 0.15434709 | G21: ='Ratio Analysis'!G21 -> 0.16257232 | H21: ='Ratio Analysis'!H21 -> 0.14968581 | I21: ='Ratio Analysis'!I21 -> 0.16522478 | J21: ='Ratio Analysis'!J21 -> 0.17004196 | ... L21: ='Ratio Analysis'!L21 -> 0.17314407
A23: # | B23: CASH FLOW
B24: Cash from Operating Activities | C24: =Forcasting!C85 -> -724 | D24: =Forcasting!D85 -> 1370 | E24: =Forcasting!E85 -> 1695 | F24: =Forcasting!F85 -> -541 | G24: =Forcasting!G85 -> 5590 | H24: =Forcasting!H85 -> 2506.8371 | I24: =Forcasting!I85 -> 2395.0331 | J24: =Forcasting!J85 -> 3828.2103 | ... L24: =Forcasting!L85 -> 6811.5612
B25: Capital Expenditure | C25: ='FA Schedule'!C7 -> 420 | D25: ='FA Schedule'!D7 -> 895 | E25: ='FA Schedule'!E7 -> 1295 | F25: ='FA Schedule'!F7 -> 1046 | G25: ='FA Schedule'!G7 -> 3642 | H25: ='FA Schedule'!H7 -> 3205.5744 | I25: ='FA Schedule'!I7 -> 3750.522 | J25: ='FA Schedule'!J7 -> 4313.1004 | ... L25: ='FA Schedule'!L7 -> 5556.1359
B26: Free Cash Flow (CFO − Capex) | C26: =Forcasting!C103 -> -1144 | D26: =Forcasting!D103 -> 475 | E26: =Forcasting!E103 -> 400 | F26: =Forcasting!F103 -> -1587 | G26: =Forcasting!G103 -> 1948 | H26: =Forcasting!H103 -> -698.73731 | I26: =Forcasting!I103 -> -1355.4889 | J26: =Forcasting!J103 -> -484.89003 | ... L26: =Forcasting!L103 -> 1255.4254
B27: Closing Cash Balance | C27: =Forcasting!C101 -> 1573 | D27: =Forcasting!D101 -> 1343 | E27: =Forcasting!E101 -> 1526 | F27: =Forcasting!F101 -> 1584 | G27: =Forcasting!G101 -> 1917 | H27: =Forcasting!H101 -> 5388.3334 | I27: =Forcasting!I101 -> 7647.7693 | J27: =Forcasting!J101 -> 10364.946 | ... L27: =Forcasting!L101 -> 15587.621
B28: Borrowings Growth % | C28: ='Debt Schedule'!C16 -> 0.29035119 | D28: ='Debt Schedule'!D16 -> 0.28756014 | E28: ='Debt Schedule'!E16 -> 0.6577346 | F28: ='Debt Schedule'!F16 -> 0.33803452 | G28: ='Debt Schedule'!G16 -> 0.47379314 | H28: ='Debt Schedule'!H16 -> 0.18 | I28: ='Debt Schedule'!I16 -> 0.15 | J28: ='Debt Schedule'!J16 -> 0.13 | ... L28: ='Debt Schedule'!L16 -> 0.09
B29: Cash Conversion Cycle (days) | C29: ='Ratio Analysis'!C36 -> 200.7012 | D29: ='Ratio Analysis'!D36 -> 179.77574 | E29: ='Ratio Analysis'!E36 -> 161.81876 | F29: ='Ratio Analysis'!F36 -> 197.76946 | G29: ='Ratio Analysis'!G36 -> 201.96107 | H29: ='Ratio Analysis'!H36 -> 186 | I29: ='Ratio Analysis'!I36 -> 186 | J29: ='Ratio Analysis'!J36 -> 186 | ... L29: ='Ratio Analysis'!L36 -> 186

Sheet Assumptions
B2: ="Assumptions - Forecast Drivers - "&'Data Sheet'!B1 -> Assumptions - Forecast Drivers - TITAN COMPANY LTD
B3: Years | C3: ='Data Sheet'!G16+(5*365) -> 46476 | D3: ='Data Sheet'!H16+(5*365) -> 46841 | E3: ='Data Sheet'!I16+(5*365) -> 47207 | F3: ='Data Sheet'!J16+(5*365) -> 47572 | G3: ='Data Sheet'!K16+(5*365) -> 47937 | H3: Notes / Rationale
B4: ₹ Values are in Cr.
A5: # | B5: Income Statement Drivers
B6: Revenue Growth % | C6: 0.22 | D6: 0.17 | E6: 0.15 | F6: 0.14 | G6: 0.13
B7: Material cost % | C7: 0.82 | D7: 0.81 | E7: 0.805 | F7: 0.805 | G7: 0.8
B8: Selling and General Expenses % | C8: 0.09 | D8: 0.09 | E8: 0.09 | F8: 0.09 | G8: 0.09
B9: EBITDA margin % | C9: =1-C7-C8 -> 0.09 | D9: =1-D7-D8 -> 0.1 | E9: =1-E7-E8 -> 0.105 | F9: =1-F7-F8 -> 0.105 | G9: =1-G7-G8 -> 0.11
B10: Other income % | C10: 0.005 | D10: 0.005 | E10: 0.005 | F10: 0.005 | G10: 0.005
B11: Effective Tax Rate % | C11: 0.252 | D11: 0.252 | E11: 0.252 | F11: 0.252 | G11: 0.252
B12: Dividend payout Ratio | C12: 0.28 | D12: 0.28 | E12: 0.28 | F12: 0.28 | G12: 0.28
A14: # | B14: Fixed Assets / Capex Drivers
B15: Capex % of Revenue | C15: 0.03 | D15: 0.03 | E15: 0.03 | F15: 0.03 | G15: 0.03
B16: Depreciation % of opening fixed assets net block | C16: 0.195 | D16: 0.195 | E16: 0.195 | F16: 0.195 | G16: 0.195
B17: Investments | C17: 3506 | D17: 3506 | E17: 3506 | F17: 3506 | G17: 3506
B18: Capital WIP | C18: 163 | D18: 163 | E18: 163 | F18: 163 | G18: 163
A20: # | B20: Working Capital Drivers
B21: Inventory days | C21: 195 | D21: 195 | E21: 195 | F21: 195 | G21: 195
B22: Receivable days | C22: 6 | D22: 6 | E22: 6 | F22: 6 | G22: 6
B23: Payable days | C23: 15 | D23: 15 | E23: 15 | F23: 15 | G23: 15
B24: Advances from customers % of revenue | C24: 0.04 | D24: 0.04 | E24: 0.04 | F24: 0.04 | G24: 0.04
B25: Other assets % of revenue | C25: 0.05 | D25: 0.05 | E25: 0.05 | F25: 0.05 | G25: 0.05
B26: Other liabilities % of revenue | C26: 0.08 | D26: 0.08 | E26: 0.08 | F26: 0.08 | G26: 0.08
B28: Finance Drivers
B29: Interest Rate (% of Average Borrowings) | C29: 0.04 | D29: 0.04 | E29: 0.04 | F29: 0.04 | G29: 0.04
B30: Borrowings Growth % | C30: 0.18 | D30: 0.15 | E30: 0.13 | F30: 0.11 | G30: 0.09
B31: Equity Shares Capital (Cr) | C31: =IFERROR('Data Sheet'!$K$57,0) -> 89 | D31: =IFERROR('Data Sheet'!$K$57,0) -> 89 | E31: =IFERROR('Data Sheet'!$K$57,0) -> 89 | F31: =IFERROR('Data Sheet'!$K$57,0) -> 89 | G31: =IFERROR('Data Sheet'!$K$57,0) -> 89
B32: Shares outstanding (Cr) | C32: =IFERROR('Data Sheet'!$B$6,0) -> 88.778613 | D32: =IFERROR('Data Sheet'!$B$6,0) -> 88.778613 | E32: =IFERROR('Data Sheet'!$B$6,0) -> 88.778613 | F32: =IFERROR('Data Sheet'!$B$6,0) -> 88.778613 | G32: =IFERROR('Data Sheet'!$B$6,0) -> 88.778613

Sheet Financials>

Sheet Historical FS
B2: ="Historical Financial Statement - "&'Data Sheet'!B1 -> Historical Financial Statement - TITAN COMPANY LTD
B3: Years | C3: ='Data Sheet'!B16 -> 42825 | D3: ='Data Sheet'!C16 -> 43190 | E3: ='Data Sheet'!D16 -> 43555 | F3: ='Data Sheet'!E16 -> 43921 | G3: ='Data Sheet'!F16 -> 44286 | H3: ='Data Sheet'!G16 -> 44651 | I3: ='Data Sheet'!H16 -> 45016 | J3: ='Data Sheet'!I16 -> 45382 | ... L3: ='Data Sheet'!K16 -> 46112 | M3: LTM
B4: ₹ Values are in Cr.
A5: # | B5: Income Statement
B6: Sales | C6: =IFERROR('Data Sheet'!B17,0) -> 13260.83 | D6: =IFERROR('Data Sheet'!C17,0) -> 16119.77 | E6: =IFERROR('Data Sheet'!D17,0) -> 19778.52 | F6: =IFERROR('Data Sheet'!E17,0) -> 21052 | G6: =IFERROR('Data Sheet'!F17,0) -> 21644 | H6: =IFERROR('Data Sheet'!G17,0) -> 28799 | I6: =IFERROR('Data Sheet'!H17,0) -> 40575 | J6: =IFERROR('Data Sheet'!I17,0) -> 51084 | ... L6: =IFERROR('Data Sheet'!K17,0) -> 87584 | M6: =IFERROR(SUM('Data Sheet'!H42:K42),0) -> 92417
B7: Sales Growth | D7: =IFERROR((D6/C6)-1,0) -> 0.21559284 | E7: =IFERROR((E6/D6)-1,0) -> 0.22697284 | F7: =IFERROR((F6/E6)-1,0) -> 0.064387022 | G7: =IFERROR((G6/F6)-1,0) -> 0.028120844 | H7: =IFERROR((H6/G6)-1,0) -> 0.3305766 | I7: =IFERROR((I6/H6)-1,0) -> 0.40890309 | J7: =IFERROR((J6/I6)-1,0) -> 0.25900185 | K7: =IFERROR((K6/J6)-1,0) -> 0.18346253 | ... M7: =IFERROR((M6/L6)-1,0) -> 0.055181312
B9: COGS | C9: =IFERROR(SUM('Data Sheet'!B18,'Data Sheet'!B20:B22)-1*'Data Sheet'!B19,0) -> 10606.01 | D9: =IFERROR(SUM('Data Sheet'!C18,'Data Sheet'!C20:C22)-1*'Data Sheet'!C19,0) -> 12762.63 | E9: =IFERROR(SUM('Data Sheet'!D18,'Data Sheet'!D20:D22)-1*'Data Sheet'!D19,0) -> 15660.48 | F9: =IFERROR(SUM('Data Sheet'!E18,'Data Sheet'!E20:E22)-1*'Data Sheet'!E19,0) -> 16626 | G9: =IFERROR(SUM('Data Sheet'!F18,'Data Sheet'!F20:F22)-1*'Data Sheet'!F19,0) -> 17661 | H9: =IFERROR(SUM('Data Sheet'!G18,'Data Sheet'!G20:G22)-1*'Data Sheet'!G19,0) -> 23225 | I9: =IFERROR(SUM('Data Sheet'!H18,'Data Sheet'!H20:H22)-1*'Data Sheet'!H19,0) -> 32295 | J9: =IFERROR(SUM('Data Sheet'!I18,'Data Sheet'!I20:I22)-1*'Data Sheet'!I19,0) -> 41664 | ... L9: =IFERROR(SUM('Data Sheet'!K18,'Data Sheet'!K20:K22)-1*'Data Sheet'!K19,0) -> 73461 | M9: =IFERROR(SUM('Data Sheet'!H43:K43),0) -> 83001
B10: COGS % Sales | C10: =IFERROR(C9/C6,0) -> 0.79979986 | D10: =IFERROR(D9/D6,0) -> 0.79173772 | E10: =IFERROR(E9/E6,0) -> 0.79179231 | F10: =IFERROR(F9/F6,0) -> 0.78975869 | G10: =IFERROR(G9/G6,0) -> 0.81597671 | H10: =IFERROR(H9/H6,0) -> 0.80645161 | I10: =IFERROR(I9/I6,0) -> 0.79593346 | J10: =IFERROR(J9/J6,0) -> 0.81559784 | ... M10: =IFERROR(M9/M6,0) -> 0.89811398
B12: Gross Profit | C12: =C6-C9 -> 2654.82 | D12: =D6-D9 -> 3357.14 | E12: =E6-E9 -> 4118.04 | F12: =F6-F9 -> 4426 | G12: =G6-G9 -> 3983 | H12: =H6-H9 -> 5574 | I12: =I6-I9 -> 8280 | J12: =J6-J9 -> 9420 | ... M12: =M6-M9 -> 9416
B13: Gross Margins | C13: =IFERROR(C12/C6,0) -> 0.20020014 | D13: =IFERROR(D12/D6,0) -> 0.20826228 | E13: =IFERROR(E12/E6,0) -> 0.20820769 | F13: =IFERROR(F12/F6,0) -> 0.21024131 | G13: =IFERROR(G12/G6,0) -> 0.18402329 | H13: =IFERROR(H12/H6,0) -> 0.19354839 | I13: =IFERROR(I12/I6,0) -> 0.20406654 | J13: =IFERROR(J12/J6,0) -> 0.18440216 | ... M13: =IFERROR(M12/M6,0) -> 0.10188602
B15: Selling & General Expenses | C15: =IFERROR(SUM('Data Sheet'!B23:B24),0) -> 1490.92 | D15: =IFERROR(SUM('Data Sheet'!C23:C24),0) -> 1712.94 | E15: =IFERROR(SUM('Data Sheet'!D23:D24),0) -> 2124.25 | F15: =IFERROR(SUM('Data Sheet'!E23:E24),0) -> 1963 | G15: =IFERROR(SUM('Data Sheet'!F23:F24),0) -> 2258 | H15: =IFERROR(SUM('Data Sheet'!G23:G24),0) -> 2230 | I15: =IFERROR(SUM('Data Sheet'!H23:H24),0) -> 3398 | J15: =IFERROR(SUM('Data Sheet'!I23:I24),0) -> 4128 | ... L15: =IFERROR(SUM('Data Sheet'!K23:K24),0) -> 5766
B16: S&G Exp % Sales | C16: =IFERROR(C15/C6,0) -> 0.11243037 | D16: =IFERROR(D15/D6,0) -> 0.1062633 | E16: =IFERROR(E15/E6,0) -> 0.10740187 | F16: =IFERROR(F15/F6,0) -> 0.093245297 | G16: =IFERROR(G15/G6,0) -> 0.10432452 | H16: =IFERROR(H15/H6,0) -> 0.077433244 | I16: =IFERROR(I15/I6,0) -> 0.083746149 | J16: =IFERROR(J15/J6,0) -> 0.080808081 | ... M16: =IFERROR(M15/M6,0) -> 0
B18: EBITDA | C18: =C12-C15 -> 1163.9 | D18: =D12-D15 -> 1644.2 | E18: =E12-E15 -> 1993.79 | F18: =F12-F15 -> 2463 | G18: =G12-G15 -> 1725 | H18: =H12-H15 -> 3344 | I18: =I12-I15 -> 4882 | J18: =J12-J15 -> 5292 | ... M18: =M12-M15 -> 9416
B19: EBITDA Margins | C19: =IFERROR(C18/C6,0) -> 0.08776977 | D19: =IFERROR(D18/D6,0) -> 0.10199897 | E19: =IFERROR(E18/E6,0) -> 0.10080582 | F19: =IFERROR(F18/F6,0) -> 0.11699601 | G19: =IFERROR(G18/G6,0) -> 0.079698762 | H19: =IFERROR(H18/H6,0) -> 0.11611514 | I19: =IFERROR(I18/I6,0) -> 0.12032039 | J19: =IFERROR(J18/J6,0) -> 0.10359408 | ... M19: =IFERROR(M18/M6,0) -> 0.10188602
B21: Other Income | C21: =IFERROR('Data Sheet'!B25,0) -> -42.38 | D21: =IFERROR('Data Sheet'!C25,0) -> 69.93 | E21: =IFERROR('Data Sheet'!D25,0) -> 178.48 | F21: =IFERROR('Data Sheet'!E25,0) -> 153 | G21: =IFERROR('Data Sheet'!F25,0) -> 180 | H21: =IFERROR('Data Sheet'!G25,0) -> 177 | I21: =IFERROR('Data Sheet'!H25,0) -> 306 | J21: =IFERROR('Data Sheet'!I25,0) -> 534 | ... L21: =IFERROR('Data Sheet'!K25,0) -> 450 | M21: =IFERROR(SUM('Data Sheet'!H44:K44),0) -> 495
B22: Other Income % Sales | C22: =IFERROR(C21/C6,0) -> -0.0031958784 | D22: =IFERROR(D21/D6,0) -> 0.0043381512 | E22: =IFERROR(E21/E6,0) -> 0.009023931 | F22: =IFERROR(F21/F6,0) -> 0.007267718 | G22: =IFERROR(G21/G6,0) -> 0.0083163925 | H22: =IFERROR(H21/H6,0) -> 0.0061460467 | I22: =IFERROR(I21/I6,0) -> 0.0075415896 | J22: =IFERROR(J21/J6,0) -> 0.010453371 | ... M22: =IFERROR(M21/M6,0) -> 0.0053561574
B24: Interest | C24: =IFERROR('Data Sheet'!B27,0) -> 37.74 | D24: =IFERROR('Data Sheet'!C27,0) -> 52.92 | E24: =IFERROR('Data Sheet'!D27,0) -> 52.54 | F24: =IFERROR('Data Sheet'!E27,0) -> 166 | G24: =IFERROR('Data Sheet'!F27,0) -> 203 | H24: =IFERROR('Data Sheet'!G27,0) -> 218 | I24: =IFERROR('Data Sheet'!H27,0) -> 300 | J24: =IFERROR('Data Sheet'!I27,0) -> 619 | ... L24: =IFERROR('Data Sheet'!K27,0) -> 1180 | M24: =IFERROR(SUM('Data Sheet'!H46:K46),0) -> 1262
B25: Interest % Sales | C25: =IFERROR(C24/C6,0) -> 0.0028459757 | D25: =IFERROR(D24/D6,0) -> 0.0032829253 | E25: =IFERROR(E24/E6,0) -> 0.0026564172 | F25: =IFERROR(F24/F6,0) -> 0.0078852366 | G25: =IFERROR(G24/G6,0) -> 0.0093790427 | H25: =IFERROR(H24/H6,0) -> 0.0075697073 | I25: =IFERROR(I24/I6,0) -> 0.0073937153 | J25: =IFERROR(J24/J6,0) -> 0.012117297 | ... M25: =IFERROR(M24/M6,0) -> 0.013655496
B27: Depreciation | C27: =IFERROR('Data Sheet'!B26,0) -> 110.53 | D27: =IFERROR('Data Sheet'!C26,0) -> 131.43 | E27: =IFERROR('Data Sheet'!D26,0) -> 162.84 | F27: =IFERROR('Data Sheet'!E26,0) -> 348 | G27: =IFERROR('Data Sheet'!F26,0) -> 375 | H27: =IFERROR('Data Sheet'!G26,0) -> 399 | I27: =IFERROR('Data Sheet'!H26,0) -> 441 | J27: =IFERROR('Data Sheet'!I26,0) -> 584 | ... L27: =IFERROR('Data Sheet'!K26,0) -> 826 | M27: =IFERROR(SUM('Data Sheet'!H45:K45),0) -> 898
B28: Depreciation%Sales | C28: =C27/C6 -> 0.008335074 | D28: =D27/D6 -> 0.0081533421 | E28: =E27/E6 -> 0.0082331742 | F28: =F27/F6 -> 0.016530496 | G28: =G27/G6 -> 0.017325818 | H28: =H27/H6 -> 0.013854648 | I28: =I27/I6 -> 0.010868762 | J28: =J27/J6 -> 0.011432151 | ... M28: =M27/M6 -> 0.009716827
B30: Earnings Before Tax | C30: =IFERROR(C18-SUM(-1*C21,C24,C27),0) -> 973.25 | D30: =IFERROR(D18-SUM(-1*D21,D24,D27),0) -> 1529.78 | E30: =IFERROR(E18-SUM(-1*E21,E24,E27),0) -> 1956.89 | F30: =IFERROR(F18-SUM(-1*F21,F24,F27),0) -> 2102 | G30: =IFERROR(G18-SUM(-1*G21,G24,G27),0) -> 1327 | H30: =IFERROR(H18-SUM(-1*H21,H24,H27),0) -> 2904 | I30: =IFERROR(I18-SUM(-1*I21,I24,I27),0) -> 4447 | J30: =IFERROR(J18-SUM(-1*J21,J24,J27),0) -> 4623 | ... M30: =IFERROR(M18-SUM(-1*M21,M24,M27),0) -> 7751
B31: EBT % Sales | C31: =C30/C6 -> 0.073392842 | D31: =D30/D6 -> 0.094900858 | E31: =E30/E6 -> 0.098940163 | F31: =F30/F6 -> 0.099847995 | G31: =G30/G6 -> 0.061310294 | H31: =H30/H6 -> 0.10083683 | I31: =I30/I6 -> 0.10959951 | J31: =J30/J6 -> 0.090498003 | ... M31: =M30/M6 -> 0.083869851
B33: Tax | C33: =IFERROR('Data Sheet'!B29,0) -> 275.97 | D33: =IFERROR('Data Sheet'!C29,0) -> 427.87 | E33: =IFERROR('Data Sheet'!D29,0) -> 568.24 | F33: =IFERROR('Data Sheet'!E29,0) -> 609 | G33: =IFERROR('Data Sheet'!F29,0) -> 353 | H33: =IFERROR('Data Sheet'!G29,0) -> 706 | I33: =IFERROR('Data Sheet'!H29,0) -> 1173 | J33: =IFERROR('Data Sheet'!I29,0) -> 1127 | ... L33: =IFERROR('Data Sheet'!K29,0) -> 1728 | M33: =IFERROR(SUM('Data Sheet'!H48:K48),0) -> 1991
B34: Effective Tax Rate | C34: =C33/C30 -> 0.2835551 | D34: =D33/D30 -> 0.27969381 | E34: =E33/E30 -> 0.29037912 | F34: =F33/F30 -> 0.28972407 | G34: =G33/G30 -> 0.26601356 | H34: =H33/H30 -> 0.24311295 | I34: =I33/I30 -> 0.26377333 | J34: =J33/J30 -> 0.24378109 | ... M34: =M33/M30 -> 0.25687008
B36: Net Profit | C36: =C30-C33 -> 697.28 | D36: =D30-D33 -> 1101.91 | E36: =E30-E33 -> 1388.65 | F36: =F30-F33 -> 1493 | G36: =G30-G33 -> 974 | H36: =H30-H33 -> 2198 | I36: =I30-I33 -> 3274 | J36: =J30-J33 -> 3496 | ... M36: =M30-M33 -> 5760
B37: Net Margins | C37: =C36/C6 -> 0.052581927 | D37: =D36/D6 -> 0.068357675 | E37: =E36/E6 -> 0.070210006 | F37: =F36/F6 -> 0.070919628 | G37: =G36/G6 -> 0.045000924 | H37: =H36/H6 -> 0.076322095 | I37: =I36/I6 -> 0.08069008 | J37: =J36/J6 -> 0.068436301 | ... M37: =M36/M6 -> 0.062326195
B39: No of Equity Shares | C39: =IFERROR('Data Sheet'!B93,0) -> 88.78 | D39: =IFERROR('Data Sheet'!C93,0) -> 88.78 | E39: =IFERROR('Data Sheet'!D93,0) -> 88.78 | F39: =IFERROR('Data Sheet'!E93,0) -> 88.78 | G39: =IFERROR('Data Sheet'!F93,0) -> 88.78 | H39: =IFERROR('Data Sheet'!G93,0) -> 88.78 | I39: =IFERROR('Data Sheet'!H93,0) -> 88.78 | J39: =IFERROR('Data Sheet'!I93,0) -> 88.78 | ... L39: =IFERROR('Data Sheet'!K93,0) -> 88.78 | M39: =IFERROR('Data Sheet'!K93,0) -> 88.78
B41: Earnings per Share | C41: =IFERROR(C36/C39,0) -> 7.8540212 | D41: =IFERROR(D36/D39,0) -> 12.411692 | E41: =IFERROR(E36/E39,0) -> 15.641473 | F41: =IFERROR(F36/F39,0) -> 16.816851 | G41: =IFERROR(G36/G39,0) -> 10.970939 | H41: =IFERROR(H36/H39,0) -> 24.757828 | I41: =IFERROR(I36/I39,0) -> 36.877675 | J41: =IFERROR(J36/J39,0) -> 39.378238 | ... M41: =IFERROR(M36/M39,0) -> 64.879477
B42: EPS Growth % | D42: =IFERROR(D41/C41-1,0) -> 0.58029773 | E42: =IFERROR(E41/D41-1,0) -> 0.26022089 | F42: =IFERROR(F41/E41-1,0) -> 0.075144925 | G42: =IFERROR(G41/F41-1,0) -> -0.34762224 | H42: =IFERROR(H41/G41-1,0) -> 1.2566735 | I42: =IFERROR(I41/H41-1,0) -> 0.48953594 | J42: =IFERROR(J41/I41-1,0) -> 0.067806964 | K42: =IFERROR(K41/J41-1,0) -> -0.045480549 | L42: =IFERROR(L41/K41-1,0) -> 0.52022775 | M42: =IFERROR(M41/K41-1,0) -> 0.72610129
B44: Dividend per Share | C44: =IFERROR('Data Sheet'!B31/'Historical FS'!C39,0) -> 2.6000225 | D44: =IFERROR('Data Sheet'!C31/'Historical FS'!D39,0) -> 3.7499437 | E44: =IFERROR('Data Sheet'!D31/'Historical FS'!E39,0) -> 5 | F44: =IFERROR('Data Sheet'!E31/'Historical FS'!F39,0) -> 4.0099121 | G44: =IFERROR('Data Sheet'!F31/'Historical FS'!G39,0) -> 4.0099121 | H44: =IFERROR('Data Sheet'!G31/'Historical FS'!H39,0) -> 7.5185853 | I44: =IFERROR('Data Sheet'!H31/'Historical FS'!I39,0) -> 10.02478 | J44: =IFERROR('Data Sheet'!I31/'Historical FS'!J39,0) -> 11.027258 | ... M44: =IFERROR('Data Sheet'!L31/'Historical FS'!M39,0) -> 0
B45: Dividend payout ratio | C45: =IFERROR(C44/C41,0) -> 0.33104348 | D45: =IFERROR(D44/D41,0) -> 0.30212994 | E45: =IFERROR(E44/E41,0) -> 0.31966298 | F45: =IFERROR(F44/F41,0) -> 0.23844608 | G45: =IFERROR(G44/G41,0) -> 0.36550308 | H45: =IFERROR(H44/H41,0) -> 0.30368517 | I45: =IFERROR(I44/I41,0) -> 0.27183873 | J45: =IFERROR(J44/J41,0) -> 0.28003432 | ... M45: =IFERROR(M44/M41,0) -> 0
B47: Retained Earnings | C47: =IFERROR(IF(C41>C44,1-C45,0),0) -> 0.66895652 | D47: =IFERROR(IF(D41>D44,1-D45,0),0) -> 0.69787006 | E47: =IFERROR(IF(E41>E44,1-E45,0),0) -> 0.68033702 | F47: =IFERROR(IF(F41>F44,1-F45,0),0) -> 0.76155392 | G47: =IFERROR(IF(G41>G44,1-G45,0),0) -> 0.63449692 | H47: =IFERROR(IF(H41>H44,1-H45,0),0) -> 0.69631483 | I47: =IFERROR(IF(I41>I44,1-I45,0),0) -> 0.72816127 | J47: =IFERROR(IF(J41>J44,1-J45,0),0) -> 0.71996568 | ... M47: =IFERROR(IF(M41>M44,1-M45,0),0) -> 1
A49: # | B49: Balance Sheet
B50: Equity Share Capital | C50: =IFERROR('Data Sheet'!B57,0) -> 88.78 | D50: =IFERROR('Data Sheet'!C57,0) -> 88.78 | E50: =IFERROR('Data Sheet'!D57,0) -> 88.78 | F50: =IFERROR('Data Sheet'!E57,0) -> 89 | G50: =IFERROR('Data Sheet'!F57,0) -> 89 | H50: =IFERROR('Data Sheet'!G57,0) -> 89 | I50: =IFERROR('Data Sheet'!H57,0) -> 89 | J50: =IFERROR('Data Sheet'!I57,0) -> 89 | ... L50: =IFERROR('Data Sheet'!K57,0) -> 89
B51: Reserves | C51: =IFERROR('Data Sheet'!B58,0) -> 4143.6 | D51: =IFERROR('Data Sheet'!C58,0) -> 5001.1 | E51: =IFERROR('Data Sheet'!D58,0) -> 5981.37 | F51: =IFERROR('Data Sheet'!E58,0) -> 6580 | G51: =IFERROR('Data Sheet'!F58,0) -> 7408 | H51: =IFERROR('Data Sheet'!G58,0) -> 9214 | I51: =IFERROR('Data Sheet'!H58,0) -> 11762 | J51: =IFERROR('Data Sheet'!I58,0) -> 9304 | ... L51: =IFERROR('Data Sheet'!K58,0) -> 15614
B52: Borrowings | C52: =IFERROR('Data Sheet'!B59,0) -> 1882.43 | D52: =IFERROR('Data Sheet'!C59,0) -> 1691.01 | E52: =IFERROR('Data Sheet'!D59,0) -> 2392.98 | F52: =IFERROR('Data Sheet'!E59,0) -> 3562 | G52: =IFERROR('Data Sheet'!F59,0) -> 5638 | H52: =IFERROR('Data Sheet'!G59,0) -> 7275 | I52: =IFERROR('Data Sheet'!H59,0) -> 9367 | J52: =IFERROR('Data Sheet'!I59,0) -> 15528 | ... L52: =IFERROR('Data Sheet'!K59,0) -> 30621
B53: Other Liabilities -
B54: Non controlling int | C54: =IFERROR('Other liabilities Data'!E4,0) -> 26 | D54: =IFERROR('Other liabilities Data'!F4,0) -> -2 | E54: =IFERROR('Other liabilities Data'!G4,0) -> 14 | F54: =IFERROR('Other liabilities Data'!H4,0) -> 4 | G54: =IFERROR('Other liabilities Data'!I4,0) -> 5 | H54: =IFERROR('Other liabilities Data'!J4,0) -> 30 | I54: =IFERROR('Other liabilities Data'!K4,0) -> 53 | J54: =IFERROR('Other liabilities Data'!L4,0) -> 0 | ... L54: =IFERROR('Other liabilities Data'!N4,0) -> 0
B55: Trade Payables | C55: =IFERROR('Other liabilities Data'!E5,0) -> 783 | D55: =IFERROR('Other liabilities Data'!F5,0) -> 878 | E55: =IFERROR('Other liabilities Data'!G5,0) -> 906 | F55: =IFERROR('Other liabilities Data'!H5,0) -> 596 | G55: =IFERROR('Other liabilities Data'!I5,0) -> 789 | H55: =IFERROR('Other liabilities Data'!J5,0) -> 1294 | I55: =IFERROR('Other liabilities Data'!K5,0) -> 1214 | J55: =IFERROR('Other liabilities Data'!L5,0) -> 1410 | ... L55: =IFERROR('Other liabilities Data'!N5,0) -> 2864
B56: Advance from Customers | C56: =IFERROR('Other liabilities Data'!E6,0) -> 943 | D56: =IFERROR('Other liabilities Data'!F6,0) -> 233 | E56: =IFERROR('Other liabilities Data'!G6,0) -> 290 | F56: =IFERROR('Other liabilities Data'!H6,0) -> 386 | G56: =IFERROR('Other liabilities Data'!I6,0) -> 479 | H56: =IFERROR('Other liabilities Data'!J6,0) -> 532 | I56: =IFERROR('Other liabilities Data'!K6,0) -> 718 | J56: =IFERROR('Other liabilities Data'!L6,0) -> 1085 | ... L56: =IFERROR('Other liabilities Data'!N6,0) -> 4745
...

Sheet Forcasting
B2: ="Forcaste - "&'Data Sheet'!B1 -> Forcaste - TITAN COMPANY LTD
B3: Years | C3: ='Historical FS'!H3 -> 44651 | D3: ='Historical FS'!I3 -> 45016 | E3: ='Historical FS'!J3 -> 45382 | F3: ='Historical FS'!K3 -> 45747 | G3: ='Historical FS'!L3 -> 46112 | H3: =+G3+365 -> 46477 | I3: =+H3+365 -> 46842 | J3: =+I3+365 -> 47207 | K3: =+J3+365 -> 47572 | L3: =+K3+365 -> 47937
B4: ₹ Values are in Cr.
A5: # | B5: Income Statement
B6: Sales | C6: =+'Historical FS'!H6 -> 28799 | D6: =+'Historical FS'!I6 -> 40575 | E6: =+'Historical FS'!J6 -> 51084 | F6: =+'Historical FS'!K6 -> 60456 | G6: =+'Historical FS'!L6 -> 87584 | H6: =IFERROR(G6*(1+H7),0) -> 106852.48 | I6: =IFERROR(H6*(1+I7),0) -> 125017.4 | J6: =IFERROR(I6*(1+J7),0) -> 143770.01 | K6: =IFERROR(J6*(1+K7),0) -> 163897.81 | L6: =IFERROR(K6*(1+L7),0) -> 185204.53
B7: Sales Growth | D7: =+'Historical FS'!I7 -> 0.40890309 | E7: =+'Historical FS'!J7 -> 0.25900185 | F7: =+'Historical FS'!K7 -> 0.18346253 | G7: =+'Historical FS'!L7 -> 0.44872304 | H7: =IFERROR(Assumptions!C6,0) -> 0.22 | I7: =IFERROR(Assumptions!D6,0) -> 0.17 | J7: =IFERROR(Assumptions!E6,0) -> 0.15 | K7: =IFERROR(Assumptions!F6,0) -> 0.14 | L7: =IFERROR(Assumptions!G6,0) -> 0.13
B9: COGS | C9: =+'Historical FS'!H9 -> 23225 | D9: =+'Historical FS'!I9 -> 32295 | E9: =+'Historical FS'!J9 -> 41664 | F9: =+'Historical FS'!K9 -> 50024 | G9: =+'Historical FS'!L9 -> 73461 | H9: =IFERROR(H6*H10,0) -> 87619.034 | I9: =IFERROR(I6*I10,0) -> 101264.1 | J9: =IFERROR(J6*J10,0) -> 115734.86 | K9: =IFERROR(K6*K10,0) -> 131937.74 | L9: =IFERROR(L6*L10,0) -> 148163.62
B10: COGS % Sales | C10: =+'Historical FS'!H10 -> 0.80645161 | D10: =+'Historical FS'!I10 -> 0.79593346 | E10: =+'Historical FS'!J10 -> 0.81559784 | F10: =+'Historical FS'!K10 -> 0.82744475 | G10: =+'Historical FS'!L10 -> 0.83874909 | H10: =IFERROR(Assumptions!C7,0) -> 0.82 | I10: =IFERROR(Assumptions!D7,0) -> 0.81 | J10: =IFERROR(Assumptions!E7,0) -> 0.805 | K10: =IFERROR(Assumptions!F7,0) -> 0.805 | L10: =IFERROR(Assumptions!G7,0) -> 0.8
B12: Gross Profit | C12: =+'Historical FS'!H12 -> 5574 | D12: =+'Historical FS'!I12 -> 8280 | E12: =+'Historical FS'!J12 -> 9420 | F12: =+'Historical FS'!K12 -> 10432 | G12: =+'Historical FS'!L12 -> 14123 | H12: =IFERROR(H6-H9,0) -> 19233.446 | I12: =IFERROR(I6-I9,0) -> 23753.306 | J12: =IFERROR(J6-J9,0) -> 28035.152 | K12: =IFERROR(K6-K9,0) -> 31960.074 | L12: =IFERROR(L6-L9,0) -> 37040.906
B13: Gross Margins | C13: =+'Historical FS'!H13 -> 0.19354839 | D13: =+'Historical FS'!I13 -> 0.20406654 | E13: =+'Historical FS'!J13 -> 0.18440216 | F13: =+'Historical FS'!K13 -> 0.17255525 | G13: =+'Historical FS'!L13 -> 0.16125091 | H13: =IFERROR(H12/H6,0) -> 0.18 | I13: =IFERROR(I12/I6,0) -> 0.19 | J13: =IFERROR(J12/J6,0) -> 0.195 | K13: =IFERROR(K12/K6,0) -> 0.195 | L13: =IFERROR(L12/L6,0) -> 0.2
B15: Selling & General Expenses | C15: =+'Historical FS'!H15 -> 2230 | D15: =+'Historical FS'!I15 -> 3398 | E15: =+'Historical FS'!J15 -> 4128 | F15: =+'Historical FS'!K15 -> 4738 | G15: =+'Historical FS'!L15 -> 5766 | H15: =+IFERROR(H6*H16,0) -> 9616.7232 | I15: =+IFERROR(I6*I16,0) -> 11251.566 | J15: =+IFERROR(J6*J16,0) -> 12939.301 | K15: =+IFERROR(K6*K16,0) -> 14750.803 | L15: =+IFERROR(L6*L16,0) -> 16668.408
B16: S&G Exp % Sales | C16: =+'Historical FS'!H16 -> 0.077433244 | D16: =+'Historical FS'!I16 -> 0.083746149 | E16: =+'Historical FS'!J16 -> 0.080808081 | F16: =+'Historical FS'!K16 -> 0.078371047 | G16: =+'Historical FS'!L16 -> 0.065833942 | H16: =IFERROR(Assumptions!C8,0) -> 0.09 | I16: =IFERROR(Assumptions!D8,0) -> 0.09 | J16: =IFERROR(Assumptions!E8,0) -> 0.09 | K16: =IFERROR(Assumptions!F8,0) -> 0.09 | L16: =IFERROR(Assumptions!G8,0) -> 0.09
B18: EBITDA | C18: =+'Historical FS'!H18 -> 3344 | D18: =+'Historical FS'!I18 -> 4882 | E18: =+'Historical FS'!J18 -> 5292 | F18: =+'Historical FS'!K18 -> 5694 | G18: =+'Historical FS'!L18 -> 8357 | H18: =IFERROR(H12-H15,0) -> 9616.7232 | I18: =IFERROR(I12-I15,0) -> 12501.74 | J18: =IFERROR(J12-J15,0) -> 15095.851 | K18: =IFERROR(K12-K15,0) -> 17209.27 | L18: =IFERROR(L12-L15,0) -> 20372.498
B19: EBITDA Margins | C19: =+'Historical FS'!H19 -> 0.11611514 | D19: =+'Historical FS'!I19 -> 0.12032039 | E19: =+'Historical FS'!J19 -> 0.10359408 | F19: =+'Historical FS'!K19 -> 0.0941842 | G19: =+'Historical FS'!L19 -> 0.095416971 | H19: =IFERROR(H18/H6,0) -> 0.09 | I19: =IFERROR(I18/I6,0) -> 0.1 | J19: =IFERROR(J18/J6,0) -> 0.105 | K19: =IFERROR(K18/K6,0) -> 0.105 | L19: =IFERROR(L18/L6,0) -> 0.11
B21: Other Income | C21: =+'Historical FS'!H21 -> 177 | D21: =+'Historical FS'!I21 -> 306 | E21: =+'Historical FS'!J21 -> 534 | F21: =+'Historical FS'!K21 -> 487 | G21: =+'Historical FS'!L21 -> 450 | H21: =IFERROR(H6*H22,0) -> 534.2624 | I21: =IFERROR(I6*I22,0) -> 625.08701 | J21: =IFERROR(J6*J22,0) -> 718.85006 | K21: =IFERROR(K6*K22,0) -> 819.48907 | L21: =IFERROR(L6*L22,0) -> 926.02265
B22: Other Income % Sales | C22: =+'Historical FS'!H22 -> 0.0061460467 | D22: =+'Historical FS'!I22 -> 0.0075415896 | E22: =+'Historical FS'!J22 -> 0.010453371 | F22: =+'Historical FS'!K22 -> 0.0080554453 | G22: =+'Historical FS'!L22 -> 0.0051379247 | H22: =IFERROR(Assumptions!C10,0) -> 0.005 | I22: =IFERROR(Assumptions!D10,0) -> 0.005 | J22: =IFERROR(Assumptions!E10,0) -> 0.005 | K22: =IFERROR(Assumptions!F10,0) -> 0.005 | L22: =IFERROR(Assumptions!G10,0) -> 0.005
B24: Interest | C24: =+'Historical FS'!H24 -> 218 | D24: =+'Historical FS'!I24 -> 300 | E24: =+'Historical FS'!J24 -> 619 | F24: =+'Historical FS'!K24 -> 953 | G24: =+'Historical FS'!L24 -> 1180 | H24: =IFERROR('Debt Schedule'!H13,0) -> 1335.0756 | I24: =IFERROR('Debt Schedule'!I13,0) -> 1553.7095 | J24: =IFERROR('Debt Schedule'!J13,0) -> 1770.1449 | K24: =IFERROR('Debt Schedule'!K13,0) -> 1981.4819 | L24: =IFERROR('Debt Schedule'!L13,0) -> 2178.5971
B25: Interest % Sales | C25: =+'Historical FS'!H25 -> 0.0075697073 | D25: =+'Historical FS'!I25 -> 0.0073937153 | E25: =+'Historical FS'!J25 -> 0.012117297 | F25: =+'Historical FS'!K25 -> 0.015763531 | G25: =+'Historical FS'!L25 -> 0.01347278 | H25: =IFERROR(H24/H6,0) -> 0.012494568 | I25: =IFERROR(I24/I6,0) -> 0.012427946 | J25: =IFERROR(J24/J6,0) -> 0.012312337 | K25: =IFERROR(K24/K6,0) -> 0.01208974 | L25: =IFERROR(L24/L6,0) -> 0.011763196
B27: Depreciation | C27: =+'Historical FS'!H27 -> 399 | D27: =+'Historical FS'!I27 -> 441 | E27: =+'Historical FS'!J27 -> 584 | F27: =+'Historical FS'!K27 -> 693 | G27: =+'Historical FS'!L27 -> 826 | H27: =IFERROR('FA Schedule'!H8,0) -> 1341.21 | I27: =IFERROR('FA Schedule'!I8,0) -> 1704.7611 | J27: =IFERROR('FA Schedule'!J8,0) -> 2103.6845 | K27: =IFERROR('FA Schedule'!K8,0) -> 2534.5206 | L27: =IFERROR('FA Schedule'!L8,0) -> 2999.0913
B28: Depreciation%Sales | C28: =+'Historical FS'!H28 -> 0.013854648 | D28: =+'Historical FS'!I28 -> 0.010868762 | E28: =+'Historical FS'!J28 -> 0.011432151 | F28: =+'Historical FS'!K28 -> 0.011462882 | G28: =+'Historical FS'!L28 -> 0.0094309463 | H28: =IFERROR(H27/H6,0) -> 0.012551978 | I28: =IFERROR(I27/I6,0) -> 0.01363619 | J28: =IFERROR(J27/J6,0) -> 0.01463229 | K28: =IFERROR(K27/K6,0) -> 0.015464029 | L28: =IFERROR(L27/L6,0) -> 0.016193401
B30: Earnings Before Tax | C30: =+'Historical FS'!H30 -> 2904 | D30: =+'Historical FS'!I30 -> 4447 | E30: =+'Historical FS'!J30 -> 4623 | F30: =+'Historical FS'!K30 -> 4535 | G30: =+'Historical FS'!L30 -> 6801 | H30: =IFERROR(H18-SUM(H21+H24+H27),0) -> 6406.1752 | I30: =IFERROR(I18-SUM(I21+I24+I27),0) -> 8618.1826 | J30: =IFERROR(J18-SUM(J21+J24+J27),0) -> 10503.172 | K30: =IFERROR(K18-SUM(K21+K24+K27),0) -> 11873.779 | L30: =IFERROR(L18-SUM(L21+L24+L27),0) -> 14268.787
B31: EBT % Sales | C31: =+'Historical FS'!H31 -> 0.10083683 | D31: =+'Historical FS'!I31 -> 0.10959951 | E31: =+'Historical FS'!J31 -> 0.090498003 | F31: =+'Historical FS'!K31 -> 0.075013233 | G31: =+'Historical FS'!L31 -> 0.077651169 | H31: =IFERROR(H30/H6,0) -> 0.059953454 | I31: =IFERROR(I30/I6,0) -> 0.068935864 | J31: =IFERROR(J30/J6,0) -> 0.073055373 | K31: =IFERROR(K30/K6,0) -> 0.072446231 | L31: =IFERROR(L30/L6,0) -> 0.077043403
B33: Tax | C33: =+'Historical FS'!H33 -> 706 | D33: =+'Historical FS'!I33 -> 1173 | E33: =+'Historical FS'!J33 -> 1127 | F33: =+'Historical FS'!K33 -> 1198 | G33: =+'Historical FS'!L33 -> 1728 | H33: =+H30*H34 -> 1614.3562 | I33: =+I30*I34 -> 2171.782 | J33: =+J30*J34 -> 2646.7993 | K33: =+K30*K34 -> 2992.1923 | L33: =+L30*L34 -> 3595.7344
B34: Effective Tax Rate | C34: =+'Historical FS'!H34 -> 0.24311295 | D34: =+'Historical FS'!I34 -> 0.26377333 | E34: =+'Historical FS'!J34 -> 0.24378109 | F34: =+'Historical FS'!K34 -> 0.26416759 | G34: =+'Historical FS'!L34 -> 0.25408028 | H34: =IFERROR(Assumptions!C11,0) -> 0.252 | I34: =IFERROR(Assumptions!D11,0) -> 0.252 | J34: =IFERROR(Assumptions!E11,0) -> 0.252 | K34: =IFERROR(Assumptions!F11,0) -> 0.252 | L34: =IFERROR(Assumptions!G11,0) -> 0.252 | M34: =H33/(H18-H27) -> 0.19507626 | N34: =I33/(I18-I27) -> 0.20114719 | O34: =J33/(J18-J27) -> 0.2037227 | P34: =K33/(K18-K27) -> 0.20390073 | Q34: =L33/(L18-L27) -> 0.20696772
B36: Net Profit | C36: =+'Historical FS'!H36 -> 2198 | D36: =+'Historical FS'!I36 -> 3274 | E36: =+'Historical FS'!J36 -> 3496 | F36: =+'Historical FS'!K36 -> 3337 | G36: =+'Historical FS'!L36 -> 5073 | H36: =IFERROR(H30-H33,0) -> 4791.819 | I36: =IFERROR(I30-I33,0) -> 6446.4006 | J36: =IFERROR(J30-J33,0) -> 7856.3725 | K36: =IFERROR(K30-K33,0) -> 8881.5866 | L36: =IFERROR(L30-L33,0) -> 10673.053
B37: Net Margins | C37: =+'Historical FS'!H37 -> 0.076322095 | D37: =+'Historical FS'!I37 -> 0.08069008 | E37: =+'Historical FS'!J37 -> 0.068436301 | F37: =+'Historical FS'!K37 -> 0.055197168 | G37: =+'Historical FS'!L37 -> 0.057921538 | H37: =IFERROR(H36/H6,0) -> 0.044845183 | I37: =IFERROR(I36/I6,0) -> 0.051564026 | J37: =IFERROR(J36/J6,0) -> 0.054645419 | K37: =IFERROR(K36/K6,0) -> 0.054189781 | L37: =IFERROR(L36/L6,0) -> 0.057628466
B39: No of Equity Shares | C39: =+'Historical FS'!H39 -> 88.78 | D39: =+'Historical FS'!I39 -> 88.78 | E39: =+'Historical FS'!J39 -> 88.78 | F39: =+'Historical FS'!K39 -> 88.78 | G39: =+'Historical FS'!L39 -> 88.78 | H39: =Assumptions!C32 -> 88.778613 | I39: =Assumptions!D32 -> 88.778613 | J39: =Assumptions!E32 -> 88.778613 | K39: =Assumptions!F32 -> 88.778613 | L39: =Assumptions!G32 -> 88.778613
B41: Earnings per Share | C41: =+'Historical FS'!H41 -> 24.757828 | D41: =+'Historical FS'!I41 -> 36.877675 | E41: =+'Historical FS'!J41 -> 39.378238 | F41: =+'Historical FS'!K41 -> 37.587294 | G41: =+'Historical FS'!L41 -> 57.141248 | H41: =IFERROR(H36/H39,0) -> 53.974926 | I41: =IFERROR(I36/I39,0) -> 72.612089 | J41: =IFERROR(J36/J39,0) -> 88.493977 | K41: =IFERROR(K36/K39,0) -> 100.04196 | L41: =IFERROR(L36/L39,0) -> 120.22099
B42: EPS Growth % | D42: =+'Historical FS'!I42 -> 0.48953594 | E42: =+'Historical FS'!J42 -> 0.067806964 | F42: =+'Historical FS'!K42 -> -0.045480549 | G42: =+'Historical FS'!L42 -> 0.52022775 | H42: =IFERROR((H41/G41)-1,0) -> -0.055412196 | I42: =IFERROR((I41/H41)-1,0) -> 0.34529298 | J42: =IFERROR((J41/I41)-1,0) -> 0.21872237 | K42: =IFERROR((K41/J41)-1,0) -> 0.13049458 | L42: =IFERROR((L41/K41)-1,0) -> 0.20170565
B44: Dividend per Share | C44: =+'Historical FS'!H44 -> 7.5185853 | D44: =+'Historical FS'!I44 -> 10.02478 | E44: =+'Historical FS'!J44 -> 11.027258 | F44: =+'Historical FS'!K44 -> 11.027258 | G44: =+'Historical FS'!L44 -> 15.037171 | H44: =IFERROR(H45*H41,0) -> 15.112979 | I44: =IFERROR(I45*I41,0) -> 20.331385 | J44: =IFERROR(J45*J41,0) -> 24.778314 | K44: =IFERROR(K45*K41,0) -> 28.011749 | L44: =IFERROR(L45*L41,0) -> 33.661878
B45: Dividend payout ratio | C45: =+'Historical FS'!H45 -> 0.30368517 | D45: =+'Historical FS'!I45 -> 0.27183873 | E45: =+'Historical FS'!J45 -> 0.28003432 | F45: =+'Historical FS'!K45 -> 0.29337728 | G45: =+'Historical FS'!L45 -> 0.26315789 | H45: =IFERROR(Assumptions!C12,0) -> 0.28 | I45: =IFERROR(Assumptions!D12,0) -> 0.28 | J45: =IFERROR(Assumptions!E12,0) -> 0.28 | K45: =IFERROR(Assumptions!F12,0) -> 0.28 | L45: =IFERROR(Assumptions!G12,0) -> 0.28
B47: Retained Earnings | C47: =+'Historical FS'!H47 -> 0.69631483 | D47: =+'Historical FS'!I47 -> 0.72816127 | E47: =+'Historical FS'!J47 -> 0.71996568 | F47: =+'Historical FS'!K47 -> 0.70662272 | G47: =+'Historical FS'!L47 -> 0.73684211 | H47: =IFERROR(IF(H41>H44,1-H45,0),0) -> 0.72 | I47: =IFERROR(IF(I41>I44,1-I45,0),0) -> 0.72 | J47: =IFERROR(IF(J41>J44,1-J45,0),0) -> 0.72 | K47: =IFERROR(IF(K41>K44,1-K45,0),0) -> 0.72 | L47: =IFERROR(IF(L41>L44,1-L45,0),0) -> 0.72
A49: # | B49: Balance Sheet
B50: Equity Share Capital | C50: =+'Historical FS'!H50 -> 89 | D50: =+'Historical FS'!I50 -> 89 | E50: =+'Historical FS'!J50 -> 89 | F50: =+'Historical FS'!K50 -> 89 | G50: =+'Historical FS'!L50 -> 89 | H50: =IFERROR(Assumptions!C31,0) -> 89 | I50: =IFERROR(Assumptions!D31,0) -> 89 | J50: =IFERROR(Assumptions!E31,0) -> 89 | K50: =IFERROR(Assumptions!F31,0) -> 89 | L50: =IFERROR(Assumptions!G31,0) -> 89 | M50: Held flat
B51: Reserves | C51: =+'Historical FS'!H51 -> 9214 | D51: =+'Historical FS'!I51 -> 11762 | E51: =+'Historical FS'!J51 -> 9304 | F51: =+'Historical FS'!K51 -> 11535 | G51: =+'Historical FS'!L51 -> 15614 | H51: =IFERROR(G51+H36-(H44*H39),0) -> 19064.11 | I51: =IFERROR(H51+I36-(I44*I39),0) -> 23705.518 | J51: =IFERROR(I51+J36-(J44*J39),0) -> 29362.106 | K51: =IFERROR(J51+K36-(K44*K39),0) -> 35756.849 | L51: =IFERROR(K51+L36-(L44*L39),0) -> 43441.447
B52: Borrowings | C52: =+'Historical FS'!H52 -> 7275 | D52: =+'Historical FS'!I52 -> 9367 | E52: =+'Historical FS'!J52 -> 15528 | F52: =+'Historical FS'!K52 -> 20777 | G52: =+'Historical FS'!L52 -> 30621 | H52: =IFERROR('Debt Schedule'!H8,0) -> 36132.78 | I52: =IFERROR('Debt Schedule'!I8,0) -> 41552.697 | J52: =IFERROR('Debt Schedule'!J8,0) -> 46954.548 | K52: =IFERROR('Debt Schedule'!K8,0) -> 52119.548 | L52: =IFERROR('Debt Schedule'!L8,0) -> 56810.307
B53: Other Liabilities -
B54: Non controlling int | C54: =IFERROR('Historical FS'!H54,0) -> 30 | D54: =IFERROR('Historical FS'!I54,0) -> 53 | E54: =IFERROR('Historical FS'!J54,0) -> 0 | F54: =IFERROR('Historical FS'!K54,0) -> 0 | G54: =IFERROR('Historical FS'!L54,0) -> 0 | H54: =+G54 -> 0 | I54: =+H54 -> 0 | J54: =+I54 -> 0 | K54: =+J54 -> 0 | L54: =+K54 -> 0 | M54: Held flat
B55: Trade Payables | C55: =IFERROR('Historical FS'!H55,0) -> 1294 | D55: =IFERROR('Historical FS'!I55,0) -> 1214 | E55: =IFERROR('Historical FS'!J55,0) -> 1410 | F55: =IFERROR('Historical FS'!K55,0) -> 1963 | G55: =IFERROR('Historical FS'!L55,0) -> 2864 | H55: =IFERROR('WC Schedule'!H12,0) -> 3600.7822 | I55: =IFERROR('WC Schedule'!I12,0) -> 4161.5382 | J55: =IFERROR('WC Schedule'!J12,0) -> 4756.2271 | K55: =IFERROR('WC Schedule'!K12,0) -> 5422.0989 | L55: =IFERROR('WC Schedule'!L12,0) -> 6088.916
B56: Advance from Customers | C56: =IFERROR('Historical FS'!H56,0) -> 532 | D56: =IFERROR('Historical FS'!I56,0) -> 718 | E56: =IFERROR('Historical FS'!J56,0) -> 1085 | F56: =IFERROR('Historical FS'!K56,0) -> 2140 | G56: =IFERROR('Historical FS'!L56,0) -> 4745 | H56: =IFERROR('WC Schedule'!H13,0) -> 4274.0992 | I56: =IFERROR('WC Schedule'!I13,0) -> 5000.6961 | J56: =IFERROR('WC Schedule'!J13,0) -> 5750.8005 | K56: =IFERROR('WC Schedule'!K13,0) -> 6555.9125 | L56: =IFERROR('WC Schedule'!L13,0) -> 7408.1812
...

Sheet FA Schedule
B2: ="Fixed Asset & Depriciation Schedule - "&'Data Sheet'!B1 -> Fixed Asset & Depriciation Schedule - TITAN COMPANY LTD
B3: Years | C3: ='Historical FS'!H3 -> 44651 | D3: ='Historical FS'!I3 -> 45016 | E3: ='Historical FS'!J3 -> 45382 | F3: ='Historical FS'!K3 -> 45747 | G3: ='Historical FS'!L3 -> 46112 | H3: =+G3+365 -> 46477 | I3: =+H3+365 -> 46842 | J3: =+I3+365 -> 47207 | K3: =+J3+365 -> 47572 | L3: =+K3+365 -> 47937
B4: ₹ Values are in Cr.
B5: Fixed Asset Net Block
B6: Opening fixed assets net block | C6: =IFERROR('Historical FS'!G60,0) -> 2523 | D6: =C9 -> 2544 | E6: =D9 -> 2998 | F6: =E9 -> 3709 | G6: =F9 -> 4062 | H6: =G9 -> 6878 | I6: =H9 -> 8742.3644 | J6: =I9 -> 10788.125 | K6: =J9 -> 12997.541 | L6: =K9 -> 15379.955
B7: (+) Capex | C7: =IFERROR(C9+C8-C6,0) -> 420 | D7: =IFERROR(D9+D8-D6,0) -> 895 | E7: =IFERROR(E9+E8-E6,0) -> 1295 | F7: =IFERROR(F9+F8-F6,0) -> 1046 | G7: =IFERROR(G9+G8-G6,0) -> 3642 | H7: =IFERROR(Forcasting!H6*Assumptions!C15,0) -> 3205.5744 | I7: =IFERROR(Forcasting!I6*Assumptions!D15,0) -> 3750.522 | J7: =IFERROR(Forcasting!J6*Assumptions!E15,0) -> 4313.1004 | K7: =IFERROR(Forcasting!K6*Assumptions!F15,0) -> 4916.9344 | L7: =IFERROR(Forcasting!L6*Assumptions!G15,0) -> 5556.1359
B8: (−) Depreciation | C8: =IFERROR('Data Sheet'!G26,0) -> 399 | D8: =IFERROR('Data Sheet'!H26,0) -> 441 | E8: =IFERROR('Data Sheet'!I26,0) -> 584 | F8: =IFERROR('Data Sheet'!J26,0) -> 693 | G8: =IFERROR('Data Sheet'!K26,0) -> 826 | H8: =IFERROR('FA Schedule'!H6*Assumptions!C16,0) -> 1341.21 | I8: =IFERROR('FA Schedule'!I6*Assumptions!D16,0) -> 1704.7611 | J8: =IFERROR('FA Schedule'!J6*Assumptions!E16,0) -> 2103.6845 | K8: =IFERROR('FA Schedule'!K6*Assumptions!F16,0) -> 2534.5206 | L8: =IFERROR('FA Schedule'!L6*Assumptions!G16,0) -> 2999.0913
B9: Closing fixed assets net block | C9: =IFERROR(Forcasting!C60,0) -> 2544 | D9: =IFERROR(Forcasting!D60,0) -> 2998 | E9: =IFERROR(Forcasting!E60,0) -> 3709 | F9: =IFERROR(Forcasting!F60,0) -> 4062 | G9: =IFERROR(Forcasting!G60,0) -> 6878 | H9: =+H6+H7-H8 -> 8742.3644 | I9: =+I6+I7-I8 -> 10788.125 | J9: =+J6+J7-J8 -> 12997.541 | K9: =+K6+K7-K8 -> 15379.955 | L9: =+L6+L7-L8 -> 17937
B11: CWIP & Investment
B12: Capital Work in Progress | C12: =IFERROR(Forcasting!C61,0) -> 85 | D12: =IFERROR(Forcasting!D61,0) -> 144 | E12: =IFERROR(Forcasting!E61,0) -> 97 | F12: =IFERROR(Forcasting!F61,0) -> 105 | G12: =IFERROR(Forcasting!G61,0) -> 163 | H12: =IFERROR(Assumptions!C18,0) -> 163 | I12: =IFERROR(Assumptions!D18,0) -> 163 | J12: =IFERROR(Assumptions!E18,0) -> 163 | K12: =IFERROR(Assumptions!F18,0) -> 163 | L12: =IFERROR(Assumptions!G18,0) -> 163
B13: Investments | C13: =IFERROR(Forcasting!C62,0) -> 294 | D13: =IFERROR(Forcasting!D62,0) -> 2515 | E13: =IFERROR(Forcasting!E62,0) -> 2345 | F13: =IFERROR(Forcasting!F62,0) -> 1988 | G13: =IFERROR(Forcasting!G62,0) -> 3506 | H13: =IFERROR(Assumptions!C17,0) -> 3506 | I13: =IFERROR(Assumptions!D17,0) -> 3506 | J13: =IFERROR(Assumptions!E17,0) -> 3506 | K13: =IFERROR(Assumptions!F17,0) -> 3506 | L13: =IFERROR(Assumptions!G17,0) -> 3506
B15: Memo
B16: Capex % of Revenue | C16: =IFERROR(C7/Forcasting!C6,0) -> 0.01458384 | D16: =IFERROR(D7/Forcasting!D6,0) -> 0.022057917 | E16: =IFERROR(E7/Forcasting!E6,0) -> 0.025350403 | F16: =IFERROR(F7/Forcasting!F6,0) -> 0.017301839 | G16: =IFERROR(G7/Forcasting!G6,0) -> 0.041582938 | H16: =IFERROR(H7/Forcasting!H6,0) -> 0.03 | I16: =IFERROR(I7/Forcasting!I6,0) -> 0.03 | J16: =IFERROR(J7/Forcasting!J6,0) -> 0.03 | ... L16: =IFERROR(L7/Forcasting!L6,0) -> 0.03
B17: Depreciation % of opening fixed assets net block | C17: =+IFERROR(C8/C6,0) -> 0.15814507 | D17: =+IFERROR(D8/D6,0) -> 0.17334906 | E17: =+IFERROR(E8/E6,0) -> 0.19479653 | F17: =+IFERROR(F8/F6,0) -> 0.18684281 | G17: =+IFERROR(G8/G6,0) -> 0.2033481 | H17: =+IFERROR(H8/H6,0) -> 0.195 | I17: =+IFERROR(I8/I6,0) -> 0.195 | J17: =+IFERROR(J8/J6,0) -> 0.195 | ... L17: =+IFERROR(L8/L6,0) -> 0.195

Sheet WC Schedule
B2: ="Working Capital Schedule - "&'Data Sheet'!B1 -> Working Capital Schedule - TITAN COMPANY LTD
B3: Years | C3: ='Historical FS'!H3 -> 44651 | D3: ='Historical FS'!I3 -> 45016 | E3: ='Historical FS'!J3 -> 45382 | F3: ='Historical FS'!K3 -> 45747 | G3: ='Historical FS'!L3 -> 46112 | H3: =+G3+365 -> 46477 | I3: =+H3+365 -> 46842 | J3: =+I3+365 -> 47207 | K3: =+J3+365 -> 47572 | L3: =+K3+365 -> 47937
B4: ₹ Values are in Cr.
B5: Operating current assets
B6: Receivables | C6: =IFERROR(Forcasting!C66,0) -> 565 | D6: =IFERROR(Forcasting!D66,0) -> 674 | E6: =IFERROR(Forcasting!E66,0) -> 1018 | F6: =IFERROR(Forcasting!F66,0) -> 1068 | G6: =IFERROR(Forcasting!G66,0) -> 916 | H6: =IFERROR(Assumptions!C22/365*Forcasting!H6,0) -> 1756.4791 | I6: =IFERROR(Assumptions!D22/365*Forcasting!I6,0) -> 2055.0806 | J6: =IFERROR(Assumptions!E22/365*Forcasting!J6,0) -> 2363.3427 | K6: =IFERROR(Assumptions!F22/365*Forcasting!K6,0) -> 2694.2106 | L6: =IFERROR(Assumptions!G22/365*Forcasting!L6,0) -> 3044.458
B7: Inventory | C7: =IFERROR(Forcasting!C67,0) -> 13609 | D7: =IFERROR(Forcasting!D67,0) -> 16584 | E7: =IFERROR(Forcasting!E67,0) -> 19051 | F7: =IFERROR(Forcasting!F67,0) -> 28184 | G7: =IFERROR(Forcasting!G67,0) -> 42743 | H7: =IFERROR(Assumptions!C21/365*Forcasting!H9,0) -> 46810.169 | I7: =IFERROR(Assumptions!D21/365*Forcasting!I9,0) -> 54099.996 | J7: =IFERROR(Assumptions!E21/365*Forcasting!J9,0) -> 61830.952 | K7: =IFERROR(Assumptions!F21/365*Forcasting!K9,0) -> 70487.286 | L7: =IFERROR(Assumptions!G21/365*Forcasting!L9,0) -> 79155.908
B8: Other assets | C8: =IFERROR(Forcasting!C63,0) -> 2518 | D8: =IFERROR(Forcasting!D63,0) -> 2762 | E8: =IFERROR(Forcasting!E63,0) -> 3801 | F8: =IFERROR(Forcasting!F63,0) -> 3654 | G8: =IFERROR(Forcasting!G63,0) -> 4438 | H8: =IFERROR(Forcasting!H6*Assumptions!C25,0) -> 5342.624 | I8: =IFERROR(Forcasting!I6*Assumptions!D25,0) -> 6250.8701 | J8: =IFERROR(Forcasting!J6*Assumptions!E25,0) -> 7188.5006 | K8: =IFERROR(Forcasting!K6*Assumptions!F25,0) -> 8194.8907 | L8: =IFERROR(Forcasting!L6*Assumptions!G25,0) -> 9260.2265
B9: Total Operating current assets | C9: =IFERROR(SUM(C6:C8),0) -> 16692 | D9: =IFERROR(SUM(D6:D8),0) -> 20020 | E9: =IFERROR(SUM(E6:E8),0) -> 23870 | F9: =IFERROR(SUM(F6:F8),0) -> 32906 | G9: =IFERROR(SUM(G6:G8),0) -> 48097 | H9: =IFERROR(SUM(H6:H8),0) -> 53909.272 | I9: =IFERROR(SUM(I6:I8),0) -> 62405.947 | J9: =IFERROR(SUM(J6:J8),0) -> 71382.796 | ... L9: =IFERROR(SUM(L6:L8),0) -> 91460.593
B11: Operating current liabilities
B12: Trade Payables | C12: =IFERROR(Forcasting!C55,0) -> 1294 | D12: =IFERROR(Forcasting!D55,0) -> 1214 | E12: =IFERROR(Forcasting!E55,0) -> 1410 | F12: =IFERROR(Forcasting!F55,0) -> 1963 | G12: =IFERROR(Forcasting!G55,0) -> 2864 | H12: =IFERROR(Assumptions!C23/365*Forcasting!H9,0) -> 3600.7822 | I12: =IFERROR(Assumptions!D23/365*Forcasting!I9,0) -> 4161.5382 | J12: =IFERROR(Assumptions!E23/365*Forcasting!J9,0) -> 4756.2271 | K12: =IFERROR(Assumptions!F23/365*Forcasting!K9,0) -> 5422.0989 | L12: =IFERROR(Assumptions!G23/365*Forcasting!L9,0) -> 6088.916
B13: Advance from Customers | C13: =IFERROR(Forcasting!C56,0) -> 532 | D13: =IFERROR(Forcasting!D56,0) -> 718 | E13: =IFERROR(Forcasting!E56,0) -> 1085 | F13: =IFERROR(Forcasting!F56,0) -> 2140 | G13: =IFERROR(Forcasting!G56,0) -> 4745 | H13: =IFERROR(Forcasting!H6*Assumptions!C24,0) -> 4274.0992 | I13: =IFERROR(Forcasting!I6*Assumptions!D24,0) -> 5000.6961 | J13: =IFERROR(Forcasting!J6*Assumptions!E24,0) -> 5750.8005 | K13: =IFERROR(Forcasting!K6*Assumptions!F24,0) -> 6555.9125 | L13: =IFERROR(Forcasting!L6*Assumptions!G24,0) -> 7408.1812
B14: Other liability items | C14: =IFERROR(Forcasting!C57,0) -> 2754 | D14: =IFERROR(Forcasting!D57,0) -> 3817 | E14: =IFERROR(Forcasting!E57,0) -> 4131 | F14: =IFERROR(Forcasting!F57,0) -> 4141 | G14: =IFERROR(Forcasting!G57,0) -> 6628 | H14: =IFERROR(Forcasting!H6*Assumptions!C26,0) -> 8548.1984 | I14: =IFERROR(Forcasting!I6*Assumptions!D26,0) -> 10001.392 | J14: =IFERROR(Forcasting!J6*Assumptions!E26,0) -> 11501.601 | K14: =IFERROR(Forcasting!K6*Assumptions!F26,0) -> 13111.825 | L14: =IFERROR(Forcasting!L6*Assumptions!G26,0) -> 14816.362
B15: Total Operating current Liabilities | C15: =IFERROR(SUM(C12:C14),0) -> 4580 | D15: =IFERROR(SUM(D12:D14),0) -> 5749 | E15: =IFERROR(SUM(E12:E14),0) -> 6626 | F15: =IFERROR(SUM(F12:F14),0) -> 8244 | G15: =IFERROR(SUM(G12:G14),0) -> 14237 | H15: =IFERROR(SUM(H12:H14),0) -> 16423.08 | I15: =IFERROR(SUM(I12:I14),0) -> 19163.626 | J15: =IFERROR(SUM(J12:J14),0) -> 22008.629 | ... L15: =IFERROR(SUM(L12:L14),0) -> 28313.46
B17: Net working capital (NWC) | C17: =IFERROR(C7+C6-C12,0) -> 12880 | D17: =IFERROR(D7+D6-D12,0) -> 16044 | E17: =IFERROR(E7+E6-E12,0) -> 18659 | F17: =IFERROR(F7+F6-F12,0) -> 27289 | G17: =IFERROR(G7+G6-G12,0) -> 40795 | H17: =IFERROR(H7+H6-H12,0) -> 44965.866 | I17: =IFERROR(I7+I6-I12,0) -> 51993.539 | J17: =IFERROR(J7+J6-J12,0) -> 59438.068 | ... L17: =IFERROR(L7+L6-L12,0) -> 76111.45
B18: Change in NWC (-ve = cash outflow) | D18: =IFERROR(C17-D17,0) -> -3164 | E18: =IFERROR(D17-E17,0) -> -2615 | F18: =IFERROR(E17-F17,0) -> -8630 | G18: =IFERROR(F17-G17,0) -> -13506 | H18: =IFERROR(G17-H17,0) -> -4170.8656 | I18: =IFERROR(H17-I17,0) -> -7027.673 | J18: =IFERROR(I17-J17,0) -> -7444.5294 | K18: =IFERROR(J17-K17,0) -> -8321.3295 | L18: =IFERROR(K17-L17,0) -> -8352.053
B19: NWC % of revenue | C19: =IFERROR(C17/Forcasting!C6,0) -> 0.44723775 | D19: =IFERROR(D17/Forcasting!D6,0) -> 0.3954159 | E19: =IFERROR(E17/Forcasting!E6,0) -> 0.36526114 | F19: =IFERROR(F17/Forcasting!F6,0) -> 0.45138613 | G19: =IFERROR(G17/Forcasting!G6,0) -> 0.46578142 | H19: =IFERROR(H17/Forcasting!H6,0) -> 0.42082192 | I19: =IFERROR(I17/Forcasting!I6,0) -> 0.41589041 | J19: =IFERROR(J17/Forcasting!J6,0) -> 0.41342466 | ... L19: =IFERROR(L17/Forcasting!L6,0) -> 0.4109589
B21: Days (Memo)
B22: Inventory days | C22: =IFERROR(C7/Forcasting!C$9*365,0) -> 213.87664 | D22: =IFERROR(D7/Forcasting!D$9*365,0) -> 187.43335 | E22: =IFERROR(E7/Forcasting!E$9*365,0) -> 166.89744 | F22: =IFERROR(F7/Forcasting!F$9*365,0) -> 205.64449 | G22: =IFERROR(G7/Forcasting!G$9*365,0) -> 212.37384 | H22: =IFERROR(H7/Forcasting!H$9*365,0) -> 195 | I22: =IFERROR(I7/Forcasting!I$9*365,0) -> 195 | J22: =IFERROR(J7/Forcasting!J$9*365,0) -> 195 | ... L22: =IFERROR(L7/Forcasting!L$9*365,0) -> 195
B23: Receivable days | C23: =IFERROR(C6/Forcasting!C$6*365,0) -> 7.1608389 | D23: =IFERROR(D6/Forcasting!D$6*365,0) -> 6.063093 | E23: =IFERROR(E6/Forcasting!E$6*365,0) -> 7.2737061 | F23: =IFERROR(F6/Forcasting!F$6*365,0) -> 6.4479952 | G23: =IFERROR(G6/Forcasting!G$6*365,0) -> 3.8173639 | H23: =IFERROR(H6/Forcasting!H$6*365,0) -> 6 | I23: =IFERROR(I6/Forcasting!I$6*365,0) -> 6 | J23: =IFERROR(J6/Forcasting!J$6*365,0) -> 6 | ... L23: =IFERROR(L6/Forcasting!L$6*365,0) -> 6
B24: Payable days | C24: =IFERROR(C12/Forcasting!C9*365,0) -> 20.336276 | D24: =IFERROR(D12/Forcasting!D9*365,0) -> 13.7207 | E24: =IFERROR(E12/Forcasting!E9*365,0) -> 12.352391 | F24: =IFERROR(F12/Forcasting!F9*365,0) -> 14.323025 | G24: =IFERROR(G12/Forcasting!G9*365,0) -> 14.230136 | H24: =IFERROR(H12/Forcasting!H9*365,0) -> 15 | I24: =IFERROR(I12/Forcasting!I9*365,0) -> 15 | J24: =IFERROR(J12/Forcasting!J9*365,0) -> 15 | ... L24: =IFERROR(L12/Forcasting!L9*365,0) -> 15

Sheet Debt Schedule
B2: ="Debt & Interest Schedule - "&'Data Sheet'!B1 -> Debt & Interest Schedule - TITAN COMPANY LTD
B3: Years | C3: ='Historical FS'!H3 -> 44651 | D3: ='Historical FS'!I3 -> 45016 | E3: ='Historical FS'!J3 -> 45382 | F3: ='Historical FS'!K3 -> 45747 | G3: ='Historical FS'!L3 -> 46112 | H3: =+G3+365 -> 46477 | I3: =+H3+365 -> 46842 | J3: =+I3+365 -> 47207 | K3: =+J3+365 -> 47572 | L3: =+K3+365 -> 47937
B4: ₹ Values are in Cr.
B5: Borrowing
B6: Opening Borrowing | C6: =IFERROR('Historical FS'!G52,0) -> 5638 | D6: =IFERROR(C8,0) -> 7275 | E6: =IFERROR(D8,0) -> 9367 | F6: =IFERROR(E8,0) -> 15528 | G6: =IFERROR(F8,0) -> 20777 | H6: =IFERROR(G8,0) -> 30621 | I6: =IFERROR(H8,0) -> 36132.78 | J6: =IFERROR(I8,0) -> 41552.697 | K6: =IFERROR(J8,0) -> 46954.548 | L6: =IFERROR(K8,0) -> 52119.548
B7: Net Borrowings / (Repayment) | C7: =IFERROR(C8-C6,0) -> 1637 | D7: =IFERROR(D8-D6,0) -> 2092 | E7: =IFERROR(E8-E6,0) -> 6161 | F7: =IFERROR(F8-F6,0) -> 5249 | G7: =IFERROR(G8-G6,0) -> 9844 | H7: =IFERROR(H8-H6,0) -> 5511.78 | I7: =IFERROR(I8-I6,0) -> 5419.917 | J7: =IFERROR(J8-J6,0) -> 5401.8506 | ... L7: =IFERROR(L8-L6,0) -> 4690.7593
B8: Closing Borrowing | C8: =IFERROR(Forcasting!C52,0) -> 7275 | D8: =IFERROR(Forcasting!D52,0) -> 9367 | E8: =IFERROR(Forcasting!E52,0) -> 15528 | F8: =IFERROR(Forcasting!F52,0) -> 20777 | G8: =IFERROR(Forcasting!G52,0) -> 30621 | H8: =IFERROR(H6*(1+Assumptions!C30),0) -> 36132.78 | I8: =IFERROR(I6*(1+Assumptions!D30),0) -> 41552.697 | J8: =IFERROR(J6*(1+Assumptions!E30),0) -> 46954.548 | K8: =IFERROR(K6*(1+Assumptions!F30),0) -> 52119.548 | L8: =IFERROR(L6*(1+Assumptions!G30),0) -> 56810.307
B10: Interest Expense
B11: Average Borrowing | C11: =IFERROR((C6+C8)/2,0) -> 6456.5 | D11: =IFERROR((D6+D8)/2,0) -> 8321 | E11: =IFERROR((E6+E8)/2,0) -> 12447.5 | F11: =IFERROR((F6+F8)/2,0) -> 18152.5 | G11: =IFERROR((G6+G8)/2,0) -> 25699 | H11: =IFERROR((H6+H8)/2,0) -> 33376.89 | I11: =IFERROR((I6+I8)/2,0) -> 38842.738 | J11: =IFERROR((J6+J8)/2,0) -> 44253.622 | ... L11: =IFERROR((L6+L8)/2,0) -> 54464.928
B12: Interest Rate (% of Average Borrowings) | C12: =IFERROR(C13/C11,0) -> 0.033764423 | D12: =IFERROR(D13/D11,0) -> 0.036053359 | E12: =IFERROR(E13/E11,0) -> 0.049728861 | F12: =IFERROR(F13/F11,0) -> 0.052499656 | G12: =IFERROR(G13/G11,0) -> 0.045916184 | H12: =IFERROR(Assumptions!C29,0) -> 0.04 | I12: =IFERROR(Assumptions!D29,0) -> 0.04 | J12: =IFERROR(Assumptions!E29,0) -> 0.04 | K12: =IFERROR(Assumptions!F29,0) -> 0.04 | L12: =IFERROR(Assumptions!G29,0) -> 0.04
B13: Interest Expense | C13: =IFERROR(Forcasting!C24,0) -> 218 | D13: =IFERROR(Forcasting!D24,0) -> 300 | E13: =IFERROR(Forcasting!E24,0) -> 619 | F13: =IFERROR(Forcasting!F24,0) -> 953 | G13: =IFERROR(Forcasting!G24,0) -> 1180 | H13: =IFERROR(H11*H12,0) -> 1335.0756 | I13: =IFERROR(I11*I12,0) -> 1553.7095 | J13: =IFERROR(J11*J12,0) -> 1770.1449 | K13: =IFERROR(K11*K12,0) -> 1981.4819 | L13: =IFERROR(L11*L12,0) -> 2178.5971
B15: Memo
B16: Borrowings Growth % | C16: =IFERROR((C8/C6-1),0) -> 0.29035119 | D16: =IFERROR((D8/D6-1),0) -> 0.28756014 | E16: =IFERROR((E8/E6-1),0) -> 0.6577346 | F16: =IFERROR((F8/F6-1),0) -> 0.33803452 | G16: =IFERROR((G8/G6-1),0) -> 0.47379314 | H16: =IFERROR((H8/H6-1),0) -> 0.18 | I16: =IFERROR((I8/I6-1),0) -> 0.15 | J16: =IFERROR((J8/J6-1),0) -> 0.13 | ... L16: =IFERROR((L8/L6-1),0) -> 0.09

Sheet Ratio Analysis
B2: =" Ratio Analysis of - " & 'Data Sheet'!B1 -> Ratio Analysis of - TITAN COMPANY LTD
B3: Years | C3: ='Historical FS'!H3 -> 44651 | D3: ='Historical FS'!I3 -> 45016 | E3: ='Historical FS'!J3 -> 45382 | F3: ='Historical FS'!K3 -> 45747 | G3: ='Historical FS'!L3 -> 46112 | H3: =+G3+365 -> 46477 | I3: =+H3+365 -> 46842 | J3: =+I3+365 -> 47207 | K3: =+J3+365 -> 47572 | L3: =+K3+365 -> 47937 | M3: Trend | N3: Mean | O3: Median
B5: SalesGrowth | D5: =IFERROR(Forcasting!D7,0) -> 0.40890309 | E5: =IFERROR(Forcasting!E7,0) -> 0.25900185 | F5: =IFERROR(Forcasting!F7,0) -> 0.18346253 | G5: =IFERROR(Forcasting!G7,0) -> 0.44872304 | H5: =IFERROR(Forcasting!H7,0) -> 0.22 | I5: =IFERROR(Forcasting!I7,0) -> 0.17 | J5: =IFERROR(Forcasting!J7,0) -> 0.15 | K5: =IFERROR(Forcasting!K7,0) -> 0.14 | L5: =IFERROR(Forcasting!L7,0) -> 0.13 | N5: =IFERROR(AVERAGE(D5:L5),0) -> 0.2344545 | O5: =IFERROR(MEDIAN(D5:L5),0) -> 0.18346253
